
2017-03-05 16:50:29,361 - SF: - INFO:
get fmtime,fctime,fcontent

2017-03-05 16:50:29,471 - SF: - INFO:
get fmtime,fctime,fcontent

2017-03-05 16:50:29,571 - SF: - INFO:
get fmtime,fctime,fcontent

2017-03-05 16:50:29,573 - SF: - ERROR:
Error msg
Traceback (most recent call last):
  File "c:\python34\lib\site-packages\ptpython\repl.py", line 62, in _on_start
    code = compile(f.read(), path, 'exec')
UnicodeDecodeError: 'gbk' codec can't decode byte 0xae in position 179: illegal multibyte sequence

During handling of the above exception, another exception occurred:

Traceback (most recent call last):
  File "codetsql.py", line 60, in fidAdd_sql
    cursor.execute('''insert into hash_code( strhash ) values( %s );''',lhs)
  File "c:\python34\lib\site-packages\mysql\connector\cursor.py", line 552, in execute
    self._handle_result(self._connection.cmd_query(stmt))
  File "c:\python34\lib\site-packages\mysql\connector\connection.py", line 490, in cmd_query
    result = self._handle_result(self._send_cmd(ServerCmd.QUERY, query))
  File "c:\python34\lib\site-packages\mysql\connector\connection.py", line 395, in _handle_result
    raise errors.get_exception(packet)
mysql.connector.errors.IntegrityError: 1062 (23000): Duplicate entry 'f468c3228b76ceb499dd5c190c22921fc5fa6723' for key 'strhash'
2017-03-05 16:50:29,575 - SF: - INFO:
fidAdd_sql--->Failed to write to Sql:
'D:\\python_learn\\__init__.py'

2017-03-05 16:50:29,576 - SF: - INFO:
get fmtime,fctime,fcontent

2017-03-05 16:50:29,690 - SF: - INFO:
get fmtime,fctime,fcontent

2017-03-05 16:50:29,826 - SF: - INFO:
get fmtime,fctime,fcontent

2017-03-05 16:50:29,944 - SF: - INFO:
get fmtime,fctime,fcontent

2017-03-05 16:50:30,047 - SF: - INFO:
get fmtime,fctime,fcontent

2017-03-05 16:50:30,190 - SF: - INFO:
get fmtime,fctime,fcontent

2017-03-05 16:50:30,302 - SF: - INFO:
get fmtime,fctime,fcontent

2017-03-05 16:50:30,424 - SF: - INFO:
get fmtime,fctime,fcontent

2017-03-05 16:50:30,531 - SF: - INFO:
get fmtime,fctime,fcontent

2017-03-05 16:50:30,612 - SF: - INFO:
get fmtime,fctime,fcontent

2017-03-05 16:50:30,614 - SF: - ERROR:
Error msg
Traceback (most recent call last):
  File "c:\python34\lib\site-packages\ptpython\repl.py", line 62, in _on_start
    code = compile(f.read(), path, 'exec')
UnicodeDecodeError: 'gbk' codec can't decode byte 0xae in position 179: illegal multibyte sequence

During handling of the above exception, another exception occurred:

Traceback (most recent call last):
  File "codetsql.py", line 60, in fidAdd_sql
    cursor.execute('''insert into hash_code( strhash ) values( %s );''',lhs)
  File "c:\python34\lib\site-packages\mysql\connector\cursor.py", line 552, in execute
    self._handle_result(self._connection.cmd_query(stmt))
  File "c:\python34\lib\site-packages\mysql\connector\connection.py", line 490, in cmd_query
    result = self._handle_result(self._send_cmd(ServerCmd.QUERY, query))
  File "c:\python34\lib\site-packages\mysql\connector\connection.py", line 395, in _handle_result
    raise errors.get_exception(packet)
mysql.connector.errors.IntegrityError: 1062 (23000): Duplicate entry 'da39a3ee5e6b4b0d3255bfef95601890afd80709' for key 'strhash'
2017-03-05 16:50:30,616 - SF: - INFO:
fidAdd_sql--->Failed to write to Sql:
'D:\\python_learn\\course\\fishc\\yuc.3.py'

2017-03-05 16:50:30,617 - SF: - INFO:
get fmtime,fctime,fcontent

2017-03-05 16:50:30,620 - SF: - ERROR:
Error msg
Traceback (most recent call last):
  File "c:\python34\lib\site-packages\ptpython\repl.py", line 62, in _on_start
    code = compile(f.read(), path, 'exec')
UnicodeDecodeError: 'gbk' codec can't decode byte 0xae in position 179: illegal multibyte sequence

During handling of the above exception, another exception occurred:

Traceback (most recent call last):
  File "codetsql.py", line 60, in fidAdd_sql
    cursor.execute('''insert into hash_code( strhash ) values( %s );''',lhs)
  File "c:\python34\lib\site-packages\mysql\connector\cursor.py", line 552, in execute
    self._handle_result(self._connection.cmd_query(stmt))
  File "c:\python34\lib\site-packages\mysql\connector\connection.py", line 490, in cmd_query
    result = self._handle_result(self._send_cmd(ServerCmd.QUERY, query))
  File "c:\python34\lib\site-packages\mysql\connector\connection.py", line 395, in _handle_result
    raise errors.get_exception(packet)
mysql.connector.errors.IntegrityError: 1062 (23000): Duplicate entry '2853847a19bc4de99054cc915d9b7d6eb39e7a1b' for key 'strhash'
2017-03-05 16:50:30,623 - SF: - INFO:
fidAdd_sql--->Failed to write to Sql:
'D:\\python_learn\\comm\\hustort_files\\my.pyserial.test.py'

2017-03-05 16:50:30,623 - SF: - INFO:
get fmtime,fctime,fcontent

2017-03-05 16:50:30,712 - SF: - INFO:
get fmtime,fctime,fcontent

2017-03-05 16:50:30,822 - SF: - INFO:
get fmtime,fctime,fcontent

2017-03-05 16:50:30,825 - SF: - ERROR:
Error msg
Traceback (most recent call last):
  File "c:\python34\lib\site-packages\ptpython\repl.py", line 62, in _on_start
    code = compile(f.read(), path, 'exec')
UnicodeDecodeError: 'gbk' codec can't decode byte 0xae in position 179: illegal multibyte sequence

During handling of the above exception, another exception occurred:

Traceback (most recent call last):
  File "codetsql.py", line 60, in fidAdd_sql
    cursor.execute('''insert into hash_code( strhash ) values( %s );''',lhs)
  File "c:\python34\lib\site-packages\mysql\connector\cursor.py", line 552, in execute
    self._handle_result(self._connection.cmd_query(stmt))
  File "c:\python34\lib\site-packages\mysql\connector\connection.py", line 490, in cmd_query
    result = self._handle_result(self._send_cmd(ServerCmd.QUERY, query))
  File "c:\python34\lib\site-packages\mysql\connector\connection.py", line 395, in _handle_result
    raise errors.get_exception(packet)
mysql.connector.errors.IntegrityError: 1062 (23000): Duplicate entry '5131a1a5be2068a5c31c3a16791b351d7da9a381' for key 'strhash'
2017-03-05 16:50:30,827 - SF: - INFO:
fidAdd_sql--->Failed to write to Sql:
'D:\\python_learn\\logging\\LOG_eg.py'

2017-03-05 16:50:30,828 - SF: - INFO:
get fmtime,fctime,fcontent

2017-03-05 16:50:30,940 - SF: - INFO:
get fmtime,fctime,fcontent

2017-03-05 16:50:31,063 - SF: - INFO:
get fmtime,fctime,fcontent

2017-03-05 16:50:31,064 - SF: - ERROR:
Error msg
Traceback (most recent call last):
  File "c:\python34\lib\site-packages\ptpython\repl.py", line 62, in _on_start
    code = compile(f.read(), path, 'exec')
UnicodeDecodeError: 'gbk' codec can't decode byte 0xae in position 179: illegal multibyte sequence

During handling of the above exception, another exception occurred:

Traceback (most recent call last):
  File "codetsql.py", line 52, in fidAdd_sql
    fcontent = ftt.readlines()
  File "c:\python34\lib\codecs.py", line 319, in decode
    (result, consumed) = self._buffer_decode(data, self.errors, final)
UnicodeDecodeError: 'utf-8' codec can't decode byte 0xb5 in position 1: invalid start byte
2017-03-05 16:50:31,066 - SF: - INFO:
fidAdd_sql--->Failed to write to Sql:
'D:\\python_learn\\tmp\\Tipssf.py'

2017-03-05 16:50:31,067 - SF: - INFO:
get fmtime,fctime,fcontent

2017-03-05 16:50:31,155 - SF: - INFO:
get fmtime,fctime,fcontent

2017-03-05 16:50:31,254 - SF: - INFO:
get fmtime,fctime,fcontent

2017-03-05 16:50:31,365 - SF: - INFO:
get fmtime,fctime,fcontent

2017-03-05 16:50:31,454 - SF: - INFO:
get fmtime,fctime,fcontent

2017-03-05 16:50:31,542 - SF: - INFO:
get fmtime,fctime,fcontent

2017-03-05 16:50:31,631 - SF: - INFO:
get fmtime,fctime,fcontent

2017-03-05 16:50:31,634 - SF: - ERROR:
Error msg
Traceback (most recent call last):
  File "c:\python34\lib\site-packages\ptpython\repl.py", line 62, in _on_start
    code = compile(f.read(), path, 'exec')
UnicodeDecodeError: 'gbk' codec can't decode byte 0xae in position 179: illegal multibyte sequence

During handling of the above exception, another exception occurred:

Traceback (most recent call last):
  File "codetsql.py", line 60, in fidAdd_sql
    cursor.execute('''insert into hash_code( strhash ) values( %s );''',lhs)
  File "c:\python34\lib\site-packages\mysql\connector\cursor.py", line 552, in execute
    self._handle_result(self._connection.cmd_query(stmt))
  File "c:\python34\lib\site-packages\mysql\connector\connection.py", line 490, in cmd_query
    result = self._handle_result(self._send_cmd(ServerCmd.QUERY, query))
  File "c:\python34\lib\site-packages\mysql\connector\connection.py", line 395, in _handle_result
    raise errors.get_exception(packet)
mysql.connector.errors.IntegrityError: 1062 (23000): Duplicate entry '608c28f2d22722c23cef434ecae58a1652dd8d11' for key 'strhash'
2017-03-05 16:50:31,636 - SF: - INFO:
fidAdd_sql--->Failed to write to Sql:
'D:\\python_learn\\meta_pro1.6\\decode.py'

2017-03-05 16:50:31,636 - SF: - INFO:
get fmtime,fctime,fcontent

2017-03-05 16:50:31,638 - SF: - ERROR:
Error msg
Traceback (most recent call last):
  File "c:\python34\lib\site-packages\ptpython\repl.py", line 62, in _on_start
    code = compile(f.read(), path, 'exec')
UnicodeDecodeError: 'gbk' codec can't decode byte 0xae in position 179: illegal multibyte sequence

During handling of the above exception, another exception occurred:

Traceback (most recent call last):
  File "codetsql.py", line 60, in fidAdd_sql
    cursor.execute('''insert into hash_code( strhash ) values( %s );''',lhs)
  File "c:\python34\lib\site-packages\mysql\connector\cursor.py", line 552, in execute
    self._handle_result(self._connection.cmd_query(stmt))
  File "c:\python34\lib\site-packages\mysql\connector\connection.py", line 490, in cmd_query
    result = self._handle_result(self._send_cmd(ServerCmd.QUERY, query))
  File "c:\python34\lib\site-packages\mysql\connector\connection.py", line 395, in _handle_result
    raise errors.get_exception(packet)
mysql.connector.errors.IntegrityError: 1062 (23000): Duplicate entry 'f468c3228b76ceb499dd5c190c22921fc5fa6723' for key 'strhash'
2017-03-05 16:50:31,640 - SF: - INFO:
fidAdd_sql--->Failed to write to Sql:
'D:\\python_learn\\course\\lhd\\__init__.py'

2017-03-05 16:50:31,641 - SF: - INFO:
get fmtime,fctime,fcontent

2017-03-05 16:50:31,731 - SF: - INFO:
get fmtime,fctime,fcontent

2017-03-05 16:50:31,841 - SF: - INFO:
get fmtime,fctime,fcontent

2017-03-05 16:50:31,924 - SF: - INFO:
get fmtime,fctime,fcontent

2017-03-05 16:50:31,926 - SF: - ERROR:
Error msg
Traceback (most recent call last):
  File "c:\python34\lib\site-packages\ptpython\repl.py", line 62, in _on_start
    code = compile(f.read(), path, 'exec')
UnicodeDecodeError: 'gbk' codec can't decode byte 0xae in position 179: illegal multibyte sequence

During handling of the above exception, another exception occurred:

Traceback (most recent call last):
  File "codetsql.py", line 60, in fidAdd_sql
    cursor.execute('''insert into hash_code( strhash ) values( %s );''',lhs)
  File "c:\python34\lib\site-packages\mysql\connector\cursor.py", line 552, in execute
    self._handle_result(self._connection.cmd_query(stmt))
  File "c:\python34\lib\site-packages\mysql\connector\connection.py", line 490, in cmd_query
    result = self._handle_result(self._send_cmd(ServerCmd.QUERY, query))
  File "c:\python34\lib\site-packages\mysql\connector\connection.py", line 395, in _handle_result
    raise errors.get_exception(packet)
mysql.connector.errors.IntegrityError: 1062 (23000): Duplicate entry 'a7f71e1341d3e18e84c49d5667b8bd3fc287e0ca' for key 'strhash'
2017-03-05 16:50:31,929 - SF: - INFO:
fidAdd_sql--->Failed to write to Sql:
'D:\\python_learn\\spider\\fc\\LOG_sf.py'

2017-03-05 16:50:31,930 - SF: - INFO:
get fmtime,fctime,fcontent

2017-03-05 16:50:32,037 - SF: - INFO:
get fmtime,fctime,fcontent

2017-03-05 16:50:32,118 - SF: - INFO:
get fmtime,fctime,fcontent

2017-03-05 16:50:32,273 - SF: - INFO:
get fmtime,fctime,fcontent

2017-03-05 16:50:32,276 - SF: - ERROR:
Error msg
Traceback (most recent call last):
  File "c:\python34\lib\site-packages\ptpython\repl.py", line 62, in _on_start
    code = compile(f.read(), path, 'exec')
UnicodeDecodeError: 'gbk' codec can't decode byte 0xae in position 179: illegal multibyte sequence

During handling of the above exception, another exception occurred:

Traceback (most recent call last):
  File "codetsql.py", line 60, in fidAdd_sql
    cursor.execute('''insert into hash_code( strhash ) values( %s );''',lhs)
  File "c:\python34\lib\site-packages\mysql\connector\cursor.py", line 552, in execute
    self._handle_result(self._connection.cmd_query(stmt))
  File "c:\python34\lib\site-packages\mysql\connector\connection.py", line 490, in cmd_query
    result = self._handle_result(self._send_cmd(ServerCmd.QUERY, query))
  File "c:\python34\lib\site-packages\mysql\connector\connection.py", line 395, in _handle_result
    raise errors.get_exception(packet)
mysql.connector.errors.IntegrityError: 1062 (23000): Duplicate entry '16b7d3f0564c3ba1ed7e8ed041f668c33b5dbed9' for key 'strhash'
2017-03-05 16:50:32,278 - SF: - INFO:
fidAdd_sql--->Failed to write to Sql:
'D:\\python_learn\\spider\\JN_1.py'

2017-03-05 16:50:32,279 - SF: - INFO:
get fmtime,fctime,fcontent

2017-03-05 16:50:32,281 - SF: - ERROR:
Error msg
Traceback (most recent call last):
  File "c:\python34\lib\site-packages\ptpython\repl.py", line 62, in _on_start
    code = compile(f.read(), path, 'exec')
UnicodeDecodeError: 'gbk' codec can't decode byte 0xae in position 179: illegal multibyte sequence

During handling of the above exception, another exception occurred:

Traceback (most recent call last):
  File "codetsql.py", line 60, in fidAdd_sql
    cursor.execute('''insert into hash_code( strhash ) values( %s );''',lhs)
  File "c:\python34\lib\site-packages\mysql\connector\cursor.py", line 552, in execute
    self._handle_result(self._connection.cmd_query(stmt))
  File "c:\python34\lib\site-packages\mysql\connector\connection.py", line 490, in cmd_query
    result = self._handle_result(self._send_cmd(ServerCmd.QUERY, query))
  File "c:\python34\lib\site-packages\mysql\connector\connection.py", line 395, in _handle_result
    raise errors.get_exception(packet)
mysql.connector.errors.IntegrityError: 1062 (23000): Duplicate entry '608c28f2d22722c23cef434ecae58a1652dd8d11' for key 'strhash'
2017-03-05 16:50:32,283 - SF: - INFO:
fidAdd_sql--->Failed to write to Sql:
'D:\\python_learn\\meta_pro1.0\\decode.py'

2017-03-05 16:50:32,284 - SF: - INFO:
get fmtime,fctime,fcontent

2017-03-05 16:50:32,384 - SF: - INFO:
get fmtime,fctime,fcontent

2017-03-05 16:50:32,473 - SF: - INFO:
get fmtime,fctime,fcontent

2017-03-05 16:50:32,579 - SF: - INFO:
get fmtime,fctime,fcontent

2017-03-05 16:50:32,661 - SF: - INFO:
get fmtime,fctime,fcontent

2017-03-05 16:50:32,761 - SF: - INFO:
get fmtime,fctime,fcontent

2017-03-05 16:50:32,763 - SF: - ERROR:
Error msg
Traceback (most recent call last):
  File "c:\python34\lib\site-packages\ptpython\repl.py", line 62, in _on_start
    code = compile(f.read(), path, 'exec')
UnicodeDecodeError: 'gbk' codec can't decode byte 0xae in position 179: illegal multibyte sequence

During handling of the above exception, another exception occurred:

Traceback (most recent call last):
  File "codetsql.py", line 60, in fidAdd_sql
    cursor.execute('''insert into hash_code( strhash ) values( %s );''',lhs)
  File "c:\python34\lib\site-packages\mysql\connector\cursor.py", line 552, in execute
    self._handle_result(self._connection.cmd_query(stmt))
  File "c:\python34\lib\site-packages\mysql\connector\connection.py", line 490, in cmd_query
    result = self._handle_result(self._send_cmd(ServerCmd.QUERY, query))
  File "c:\python34\lib\site-packages\mysql\connector\connection.py", line 395, in _handle_result
    raise errors.get_exception(packet)
mysql.connector.errors.IntegrityError: 1062 (23000): Duplicate entry '5131a1a5be2068a5c31c3a16791b351d7da9a381' for key 'strhash'
2017-03-05 16:50:32,765 - SF: - INFO:
fidAdd_sql--->Failed to write to Sql:
'D:\\python_learn\\spider\\bk.LOG_eg.py'

2017-03-05 16:50:32,766 - SF: - INFO:
get fmtime,fctime,fcontent

2017-03-05 16:50:32,768 - SF: - ERROR:
Error msg
Traceback (most recent call last):
  File "c:\python34\lib\site-packages\ptpython\repl.py", line 62, in _on_start
    code = compile(f.read(), path, 'exec')
UnicodeDecodeError: 'gbk' codec can't decode byte 0xae in position 179: illegal multibyte sequence

During handling of the above exception, another exception occurred:

Traceback (most recent call last):
  File "codetsql.py", line 60, in fidAdd_sql
    cursor.execute('''insert into hash_code( strhash ) values( %s );''',lhs)
  File "c:\python34\lib\site-packages\mysql\connector\cursor.py", line 552, in execute
    self._handle_result(self._connection.cmd_query(stmt))
  File "c:\python34\lib\site-packages\mysql\connector\connection.py", line 490, in cmd_query
    result = self._handle_result(self._send_cmd(ServerCmd.QUERY, query))
  File "c:\python34\lib\site-packages\mysql\connector\connection.py", line 395, in _handle_result
    raise errors.get_exception(packet)
mysql.connector.errors.IntegrityError: 1062 (23000): Duplicate entry '28965ca12be4abc6f9154df1f53d8aa4bbe7be97' for key 'strhash'
2017-03-05 16:50:32,773 - SF: - INFO:
fidAdd_sql--->Failed to write to Sql:
'D:\\python_learn\\logo\\his\\decode.py'

2017-03-05 16:50:32,775 - SF: - INFO:
get fmtime,fctime,fcontent

2017-03-05 16:50:32,883 - SF: - INFO:
get fmtime,fctime,fcontent

2017-03-05 16:50:32,982 - SF: - INFO:
get fmtime,fctime,fcontent

2017-03-05 16:50:33,094 - SF: - INFO:
get fmtime,fctime,fcontent

2017-03-05 16:50:33,183 - SF: - INFO:
get fmtime,fctime,fcontent

2017-03-05 16:50:33,271 - SF: - INFO:
get fmtime,fctime,fcontent

2017-03-05 16:50:33,384 - SF: - INFO:
get fmtime,fctime,fcontent

2017-03-05 16:50:33,530 - SF: - INFO:
get fmtime,fctime,fcontent

2017-03-05 16:50:33,532 - SF: - ERROR:
Error msg
Traceback (most recent call last):
  File "c:\python34\lib\site-packages\ptpython\repl.py", line 62, in _on_start
    code = compile(f.read(), path, 'exec')
UnicodeDecodeError: 'gbk' codec can't decode byte 0xae in position 179: illegal multibyte sequence

During handling of the above exception, another exception occurred:

Traceback (most recent call last):
  File "codetsql.py", line 60, in fidAdd_sql
    cursor.execute('''insert into hash_code( strhash ) values( %s );''',lhs)
  File "c:\python34\lib\site-packages\mysql\connector\cursor.py", line 552, in execute
    self._handle_result(self._connection.cmd_query(stmt))
  File "c:\python34\lib\site-packages\mysql\connector\connection.py", line 490, in cmd_query
    result = self._handle_result(self._send_cmd(ServerCmd.QUERY, query))
  File "c:\python34\lib\site-packages\mysql\connector\connection.py", line 395, in _handle_result
    raise errors.get_exception(packet)
mysql.connector.errors.IntegrityError: 1062 (23000): Duplicate entry 'b27234a90c13d7f62a1a34318c0e5b31d50a0f1b' for key 'strhash'
2017-03-05 16:50:33,535 - SF: - INFO:
fidAdd_sql--->Failed to write to Sql:
'D:\\python_learn\\codein\\fortest\\GetFileHash.py'

2017-03-05 16:50:33,536 - SF: - INFO:
get fmtime,fctime,fcontent

2017-03-05 16:50:33,630 - SF: - INFO:
get fmtime,fctime,fcontent

2017-03-05 16:50:33,736 - SF: - INFO:
get fmtime,fctime,fcontent

2017-03-05 16:50:33,862 - SF: - INFO:
get fmtime,fctime,fcontent

2017-03-05 16:50:34,006 - SF: - INFO:
FailCount: 26

2017-03-05 16:50:34,007 - SF: - INFO:
OkCount: 135